<mujocoinclude>
    <body name="gripper_link" pos="0.069744 0 0">
        <body name="gripper_center_body" pos="0.15 0 0.0" quat="1 0 0 0">
            <site pos="0 0 0" size="100 100 100" name="gripper_center" rgba="1 0 1 1" type="box" group="4"/>
            <body name="gripper_center" />
        </body>
        <geom pos="-0.02 0 0" quat="0.707107 0 0 0.707107" type="mesh" mesh="vx300s_7_gripper" name="7_gripper"
              material="grippergreen"/>
        <geom pos="-0.020175 0 0" quat="0.707107 0 0 0.707107" type="mesh" mesh="vx300s_9_gripper_bar"
              name="9_gripper_bar" material="grippergreen"/>
        <body name="gripper_prop_link" pos="0.0485 0 0">
            <geom pos="-0.0685 0 0" quat="0.707107 0 0 0.707107" type="mesh" mesh="vx300s_8_gripper_prop"
                  name="8_gripper_prop" material="grippergreen"/>
        </body>
        <body name="left_finger_link" pos="0.0687 0.0 0">
            <inertial pos="0.017344 -0.0060692 0" quat="0.449364 0.449364 -0.54596 -0.54596" mass="0.034796"
                      diaginertia="2.48003e-05 1.417e-05 1.20797e-05"/>
            <joint name="left_finger" pos="0 0 0" axis="0 1 0" type="slide" limited="true" range="0.0 0.036"
                   frictionloss="30" class="gripper"/>
            <geom condim="4" solimp="2 1 0.01" solref="0.01 1" friction="4 0.1 0.01" pos="0.005 -0.03 0"
                  euler="3.14 1.57 0" type="mesh" mesh="vx300s_10_gripper_finger_left"
                  name="vx300s_left/10_left_gripper_finger" material="grippergreen"/>
            <site name="left_grip_site" pos="0.075 -0.01 0" size="0.005"/>
<!--            <body name="left_grip_site_body" pos="0.075 -0.01 0">-->
<!--                <geom type="capsule" fromto="0 0.01 0 0 0.01 0.01" size="0.005" contype="0" conaffinity="0"-->
<!--                      material="grippergreen"/>-->
<!--            </body>-->
        </body>
        <body name="right_finger_link" pos="0.0687 0 0">
            <inertial pos="0.017344 0.0060692 0" quat="0.44937 -0.44937 0.545955 -0.545955" mass="0.034796"
                      diaginertia="2.48002e-05 1.417e-05 1.20798e-05"/>
            <joint name="right_finger" pos="0 0 0" axis="0 1 0" type="slide" limited="true" range="-0.036 0.0"
                   frictionloss="30" class="gripper"/>
            <geom condim="4" solimp="2 1 0.01" solref="0.01 1" friction="4 0.1 0.01" pos="0.005 0.03 0"
                  euler="3.14 1.57 0" type="mesh" mesh="vx300s_10_gripper_finger_right"
                  name="vx300s_left/10_right_gripper_finger" material="grippergreen"/>
            <site name="right_grip_site" pos="0.075 -0.01 0" size="0.005"/>
<!--            <body name="right_grip_site_body" pos="0.075 -0.01 0">-->
<!--                <geom type="capsule" fromto="0 0.01 0 0 0.01 0.01" size="0.005" contype="0" conaffinity="0"-->
<!--                      material="grippergreen"/>-->
<!--            </body>-->
        </body>
    </body>
</mujocoinclude>